[2024-12-15 16:00:10,661: INFO: main: Welcome to our custom log ]
[2024-12-15 16:02:22,964: INFO: main: Welcome to our custom log ]
[2024-12-15 19:27:10,114: INFO: test_logger: Testing logger from main script.]
[2024-12-15 19:27:10,115: INFO: common: This is an example log message from common.py.]
[2024-12-16 21:48:36,533: ERROR: 2849332435: An error occurred: [Errno 2] No such file or directory: 'config\\config.yaml']
[2024-12-17 09:28:46,116: INFO: common: yaml file: config\config.yaml loaded successfully]
[2024-12-17 09:28:46,119: INFO: common: yaml file: params.yaml loaded successfully]
[2024-12-17 09:28:46,121: INFO: common: created directory at: artifacts]
[2024-12-17 09:28:46,123: INFO: common: created directory at: artifacts/data_ingestion]
[2024-12-17 09:28:46,124: INFO: 3172177572: Downloading data from https://drive.google.com/file/d/1vlhZ5c7abUKF8xXERIw6m9Te8fW7ohw3/view?usp=sharing into file artifacts/data_ingestion/data.zip]
[2024-12-17 09:29:01,240: INFO: 3172177572: Downloaded data from https://drive.google.com/file/d/1vlhZ5c7abUKF8xXERIw6m9Te8fW7ohw3/view?usp=sharing into file artifacts/data_ingestion/data.zip]
[2024-12-17 10:27:26,556: INFO: main: >>>>>> stage Data Ingestion stage started <<<<<<]
[2024-12-17 10:27:26,558: INFO: common: yaml file: config\config.yaml loaded successfully]
[2024-12-17 10:27:26,559: INFO: common: yaml file: params.yaml loaded successfully]
[2024-12-17 10:27:26,559: INFO: common: created directory at: artifacts]
[2024-12-17 10:27:26,559: INFO: common: created directory at: artifacts/data_ingestion]
[2024-12-17 10:27:26,560: INFO: data_ingestion: Downloading data from https://drive.google.com/file/d/1vlhZ5c7abUKF8xXERIw6m9Te8fW7ohw3/view?usp=sharing into file artifacts/data_ingestion/data.zip]
[2024-12-17 11:08:30,547: INFO: main: >>>>>> stage Data Ingestion stage started <<<<<<]
[2024-12-17 11:08:30,549: INFO: common: yaml file: config\config.yaml loaded successfully]
[2024-12-17 11:08:30,550: INFO: common: yaml file: params.yaml loaded successfully]
[2024-12-17 11:08:30,550: INFO: common: created directory at: artifacts]
[2024-12-17 11:08:30,550: INFO: common: created directory at: artifacts/data_ingestion]
[2024-12-17 11:08:30,550: INFO: data_ingestion: Downloading data from https://drive.google.com/file/d/1vlhZ5c7abUKF8xXERIw6m9Te8fW7ohw3/view?usp=sharing into file artifacts/data_ingestion/data.zip]
[2024-12-17 11:26:16,614: ERROR: main: ('Connection broken: IncompleteRead(48898695 bytes read, 8815257 more expected)', IncompleteRead(48898695 bytes read, 8815257 more expected))]
Traceback (most recent call last):
  File "C:\Users\Moussany\Desktop\deep_learning\Kidney-disease-Classification-MLFLOW-DVC\kidney\lib\site-packages\urllib3\response.py", line 748, in _error_catcher
    yield
  File "C:\Users\Moussany\Desktop\deep_learning\Kidney-disease-Classification-MLFLOW-DVC\kidney\lib\site-packages\urllib3\response.py", line 894, in _raw_read
    raise IncompleteRead(self._fp_bytes_read, self.length_remaining)
urllib3.exceptions.IncompleteRead: IncompleteRead(48898695 bytes read, 8815257 more expected)

The above exception was the direct cause of the following exception:

Traceback (most recent call last):
  File "C:\Users\Moussany\Desktop\deep_learning\Kidney-disease-Classification-MLFLOW-DVC\kidney\lib\site-packages\requests\models.py", line 820, in generate
    yield from self.raw.stream(chunk_size, decode_content=True)
  File "C:\Users\Moussany\Desktop\deep_learning\Kidney-disease-Classification-MLFLOW-DVC\kidney\lib\site-packages\urllib3\response.py", line 1060, in stream
    data = self.read(amt=amt, decode_content=decode_content)
  File "C:\Users\Moussany\Desktop\deep_learning\Kidney-disease-Classification-MLFLOW-DVC\kidney\lib\site-packages\urllib3\response.py", line 977, in read
    data = self._raw_read(amt)
  File "C:\Users\Moussany\Desktop\deep_learning\Kidney-disease-Classification-MLFLOW-DVC\kidney\lib\site-packages\urllib3\response.py", line 872, in _raw_read
    with self._error_catcher():
  File "C:\Users\Moussany\AppData\Local\Programs\Python\Python310\lib\contextlib.py", line 153, in __exit__
    self.gen.throw(typ, value, traceback)
  File "C:\Users\Moussany\Desktop\deep_learning\Kidney-disease-Classification-MLFLOW-DVC\kidney\lib\site-packages\urllib3\response.py", line 772, in _error_catcher
    raise ProtocolError(arg, e) from e
urllib3.exceptions.ProtocolError: ('Connection broken: IncompleteRead(48898695 bytes read, 8815257 more expected)', IncompleteRead(48898695 bytes read, 8815257 more expected))

During handling of the above exception, another exception occurred:

Traceback (most recent call last):
  File "C:\Users\Moussany\Desktop\deep_learning\Kidney-disease-Classification-MLFLOW-DVC\main.py", line 8, in <module>
    obj.main()
  File "C:\Users\Moussany\Desktop\deep_learning\Kidney-disease-Classification-MLFLOW-DVC\src\cnnClassifier\pipeline\stage_01_data_ingestion.py", line 17, in main
    data_ingestion.download_file()
  File "C:\Users\Moussany\Desktop\deep_learning\Kidney-disease-Classification-MLFLOW-DVC\src\cnnClassifier\components\data_ingestion.py", line 35, in download_file
    raise e
  File "C:\Users\Moussany\Desktop\deep_learning\Kidney-disease-Classification-MLFLOW-DVC\src\cnnClassifier\components\data_ingestion.py", line 30, in download_file
    gdown.download(prefix+file_id,zip_download_dir)
  File "C:\Users\Moussany\Desktop\deep_learning\Kidney-disease-Classification-MLFLOW-DVC\kidney\lib\site-packages\gdown\download.py", line 368, in download
    for chunk in res.iter_content(chunk_size=CHUNK_SIZE):
  File "C:\Users\Moussany\Desktop\deep_learning\Kidney-disease-Classification-MLFLOW-DVC\kidney\lib\site-packages\requests\models.py", line 822, in generate
    raise ChunkedEncodingError(e)
requests.exceptions.ChunkedEncodingError: ('Connection broken: IncompleteRead(48898695 bytes read, 8815257 more expected)', IncompleteRead(48898695 bytes read, 8815257 more expected))
